<?xml version="1.0" ?>
<!-- ============================================================================================= -->
<!-- |    This document was autogenerated by xacro from ur_description/urdf/ur5_robot.urdf.xacro | -->
<!-- |    EDITING THIS FILE BY HAND IS NOT RECOMMENDED                                           | -->
<!-- ============================================================================================= -->
<robot name="ur5" xmlns:xacro="http://ros.org/wiki/xacro">
  <material name="LightGrey">
    <color rgba="0.8 0.8 0.8 1.0"/>
  </material>

  <material name="DarkGrey">
    <color rgba="0.2 0.2 0.2 1.0"/>
  </material>

  <link name="base_link">
    <visual>
      <geometry>
        <mesh filename="visual/base_extended.stl"/> <!-- 使用放大的STL文件 -->
      </geometry>
      <material name="LightGrey"/>
    </visual>
    <!-- <collision>
      <geometry>
      	<mesh filename="collision/base.stl"/>
      </geometry>
    </collision> -->
    <inertial>
      <mass value="32.0"/> <!-- 质量放大8倍 -->
      <origin rpy="0 0 0" xyz="0.0 0.0 0.0"/>
      <inertia ixx="0.07093330496" ixy="0.0" ixz="0.0" iyy="0.07093330496" iyz="0.0" izz="0.1152"/> <!-- 惯性张量放大16倍 -->
    </inertial>
  </link>
  <joint name="shoulder_pan_joint" type="revolute">
    <parent link="base_link"/>
    <child link="shoulder_link"/>
    <origin rpy="0.0 0.0 0.0" xyz="0.0 0.0 0.178318"/> <!-- 原点位置放大2倍 -->
    <axis xyz="0 0 1"/>
    <limit effort="150.0" lower="-6.28318530718" upper="6.28318530718" velocity="3.15"/>
    <dynamics damping="0.0" friction="0.0"/>
  </joint>
  <link name="shoulder_link">
    <visual>
      <geometry>
        <mesh filename="visual/shoulder_extended.stl"/> <!-- 使用放大的STL文件 -->
      </geometry>
      <material name="DarkGrey"/>
    </visual>
    <collision>
      <geometry>
        <mesh filename="collision/shoulder_extended.stl"/> <!-- 使用放大的STL文件 -->
      </geometry>
    </collision>
    <inertial>
      <mass value="29.6"/> <!-- 质量放大8倍 -->
      <origin rpy="0 0 0" xyz="0.0 0.0 0.0"/>
      <inertia ixx="0.164279934288" ixy="0.0" ixz="0.0" iyy="0.164279934288" iyz="0.0" izz="0.10656"/> <!-- 惯性张量放大16倍 -->
    </inertial>
  </link>
  <joint name="shoulder_lift_joint" type="revolute">
    <parent link="shoulder_link"/>
    <child link="upper_arm_link"/>
    <origin rpy="0.0 1.57079632679 0.0" xyz="0.0 0.2717 0.0"/> <!-- 原点位置放大2倍 -->
    <axis xyz="0 1 0"/>
    <limit effort="150.0" lower="-6.28318530718" upper="6.28318530718" velocity="3.15"/>
    <dynamics damping="0.0" friction="0.0"/>
  </joint>
  <link name="upper_arm_link">
    <visual>
      <geometry>
        <mesh filename="visual/upperarm_extended.stl"/> <!-- 使用放大的STL文件 -->
      </geometry>
      <material name="LightGrey"/>
    </visual>
    <collision>
      <geometry>
        <mesh filename="collision/upperarm_extended.stl"/> <!-- 使用放大的STL文件 -->
      </geometry>
    </collision>
    <inertial>
      <mass value="67.144"/> <!-- 质量放大8倍 -->
      <origin rpy="0 0 0" xyz="0.0 0.0 0.56"/> <!-- 原点位置放大2倍 -->
      <inertia ixx="3.63013140688" ixy="0.0" ixz="0.0" iyy="3.63013140688" iyz="0.0" izz="0.2417184"/> <!-- 惯性张量放大16倍 -->
    </inertial>
  </link>
  <joint name="elbow_joint" type="revolute">
    <parent link="upper_arm_link"/>
    <child link="forearm_link"/>
    <origin rpy="0.0 0.0 0.0" xyz="0.0 -0.2394 0.85"/> <!-- 原点位置放大2倍 -->
    <axis xyz="0 1 0"/>
    <limit effort="150.0" lower="-3.14159265359" upper="3.14159265359" velocity="3.15"/>
    <dynamics damping="0.0" friction="0.0"/>
  </joint>
  <link name="forearm_link">
    <visual>
      <geometry>
        <mesh filename="visual/forearm_extended.stl"/> <!-- 使用放大的STL文件 -->
      </geometry>
      <material name="DarkGrey"/>
    </visual>
    <collision>
      <geometry>
        <mesh filename="collision/forearm_extended.stl"/> <!-- 使用放大的STL文件 -->
      </geometry>
    </collision>
    <inertial>
      <mass value="18.2"/> <!-- 质量放大8倍 -->
      <origin rpy="0 0 0" xyz="0.0 0.0 0.5"/> <!-- 原点位置放大2倍 -->
      <inertia ixx="0.791090116896" ixy="0.0" ixz="0.0" iyy="0.791090116896" iyz="0.0" izz="0.06552"/> <!-- 惯性张量放大16倍 -->
    </inertial>
  </link>
  <joint name="wrist_1_joint" type="revolute">
    <parent link="forearm_link"/>
    <child link="wrist_1_link"/>
    <origin rpy="0.0 1.57079632679 0.0" xyz="0.0 0.0 0.7845"/> <!-- 原点位置放大2倍 -->
    <axis xyz="0 1 0"/>
    <limit effort="28.0" lower="-6.28318530718" upper="6.28318530718" velocity="3.2"/>
    <dynamics damping="0.0" friction="0.0"/>
  </joint>
  <link name="wrist_1_link">
    <visual>
      <geometry>
        <mesh filename="visual/wrist1_extended.stl"/> <!-- 使用放大的STL文件 -->
      </geometry>
      <material name="LightGrey"/>
    </visual>
    <collision>
      <geometry>
        <mesh filename="collision/wrist1_extended.stl"/> <!-- 使用放大的STL文件 -->
      </geometry>
    </collision>
    <inertial>
      <mass value="9.752"/> <!-- 质量放大8倍 -->
      <origin rpy="0 0 0" xyz="0.0 0.0 0.0"/>
      <inertia ixx="1.778764088496" ixy="0.0" ixz="0.0" iyy="1.778764088496" iyz="0.0" izz="3.51072"/> <!-- 惯性张量放大16倍 -->
    </inertial>
  </link>
  <joint name="wrist_2_joint" type="revolute">
    <parent link="wrist_1_link"/>
    <child link="wrist_2_link"/>
    <origin rpy="0.0 0.0 0.0" xyz="0.0 0.186 0.0"/> <!-- 原点位置放大2倍 -->
    <axis xyz="0 0 1"/>
    <limit effort="28.0" lower="-6.28318530718" upper="6.28318530718" velocity="3.2"/>
    <dynamics damping="0.0" friction="0.0"/>
  </joint>
  <link name="wrist_2_link">
    <visual>
      <geometry>
        <mesh filename="visual/wrist2_extended.stl"/> <!-- 使用放大的STL文件 -->
      </geometry>
      <material name="DarkGrey"/>
    </visual>
    <collision>
      <geometry>
        <mesh filename="collision/wrist2_extended.stl"/> <!-- 使用放大的STL文件 -->
      </geometry>
    </collision>
    <inertial>
      <mass value="9.752"/> <!-- 质量放大8倍 -->
      <origin rpy="0 0 0" xyz="0.0 0.0 0.0"/>
      <inertia ixx="1.778764088496" ixy="0.0" ixz="0.0" iyy="1.778764088496" iyz="0.0" izz="3.51072"/> <!-- 惯性张量放大16倍 -->
    </inertial>
  </link>
  <joint name="wrist_3_joint" type="revolute">
    <parent link="wrist_2_link"/>
    <child link="wrist_3_link"/>
    <origin rpy="0.0 0.0 0.0" xyz="0.0 0.0 0.1893"/> <!-- 原点位置放大2倍 -->
    <axis xyz="0 1 0"/>
    <limit effort="28.0" lower="-6.28318530718" upper="6.28318530718" velocity="3.2"/>
    <dynamics damping="0.0" friction="0.0"/>
  </joint>
  <link name="wrist_3_link">
    <visual>
      <geometry>
        <mesh filename="visual/wrist3_extended.stl"/> <!-- 使用放大的STL文件 -->
      </geometry>
      <material name="LightGrey"/>
    </visual>
    <collision>
      <geometry>
        <mesh filename="collision/wrist3_extended.stl"/> <!-- 使用放大的STL文件 -->
      </geometry>
    </collision>
    <inertial>
      <mass value="1.5032"/> <!-- 质量放大8倍 -->
      <origin rpy="0 0 0" xyz="0.0 0.0 0.0"/>
      <inertia ixx="0.2741835703264" ixy="0.0" ixz="0.0" iyy="0.2741835703264" iyz="0.0" izz="0.541152"/> <!-- 惯性张量放大16倍 -->
    </inertial>
  </link>
  <joint name="ee_fixed_joint" type="fixed">
    <parent link="wrist_3_link"/>
    <child link="ee_link"/>
    <origin rpy="-1.5707963267948966 0.0 0.0" xyz="0.0 0.1646 0.0"/> <!-- 原点位置放大2倍 -->
  </joint>
  <link name="ee_link">
    <collision>
      <geometry>
        <box size="0.02 0.02 0.02"/> <!-- 大小放大2倍 -->
      </geometry>
      <origin rpy="0 0 0" xyz="-0.02 0 0"/> <!-- 原点位置放大2倍 -->
    </collision>
    <inertial>
      <mass value="0.0"/>
      <origin rpy="0 0 0" xyz="0.0 0.0 0.0"/>
      <inertia ixx="0.0" ixy="0.0" ixz="0.0" iyy="0.0" iyz="0.0" izz="0.0"/>
    </inertial>
  </link>
  <!-- nothing to do here at the moment -->
  <!-- ROS base_link to UR 'Base' Coordinates transform -->
  <link name="base">
    <inertial>
      <mass value="0.0"/>
      <origin rpy="0 0 0" xyz="0.0 0.0 0.0"/>
      <inertia ixx="0.0" ixy="0.0" ixz="0.0" iyy="0.0" iyz="0.0" izz="0.0"/>
    </inertial>
  </link>
  <joint name="base_link-base_fixed_joint" type="fixed">
    <!-- NOTE: this rotation is only needed as long as base_link itself is
                 not corrected wrt the real robot (ie: rotated over 180
                 degrees)
      -->
    <origin rpy="0 0 -3.14159265359" xyz="0 0 0"/>
    <parent link="base_link"/>
    <child link="base"/>
  </joint>
  <!-- Frame coincident with all-zeros TCP on UR controller -->
  <link name="tool0">
    <inertial>
      <mass value="0.0"/>
      <origin rpy="0 0 0" xyz="0.0 0.0 0.0"/>
      <inertia ixx="0.0" ixy="0.0" ixz="0.0" iyy="0.0" iyz="0.0" izz="0.0"/>
    </inertial>
  </link>
  <joint name="wrist_3_link-tool0_fixed_joint" type="fixed">
    <origin rpy="-1.57079632679 0 0" xyz="0 0.1646 0"/> <!-- 原点位置放大2倍 -->
    <parent link="wrist_3_link"/>
    <child link="tool0"/>
  </joint>

  <link name="tool_tip">
    <inertial>
      <mass value="0.0"/>
      <origin rpy="3.14159265359 0 -1.57079632679" xyz="0.0 0.0 0.0"/>
      <inertia ixx="0.0" ixy="0.0" ixz="0.0" iyy="0.0" iyz="0.0" izz="0.0"/>
    </inertial>
    <!-- <visual>
      <geometry>
        <box size="0.01 0.01 0.01"/>
      </geometry>
      <origin rpy="0 0 0" xyz="0 0 0"/>
    </visual> -->
  </link>
  <joint name="tool0-tool_tip" type="fixed">
    <origin rpy="0 0 0" xyz="0 0 0.24"/> <!-- 原点位置放大2倍 -->
    <parent link="tool0"/>
    <child link="tool_tip"/>
  </joint>

  <link name="world"/>
  <joint name="world_joint" type="fixed">
    <parent link="world"/>
    <child link="rotated_base_link"/>
    <origin rpy="0.0 0.0 0.0" xyz="0.0 0.0 0.0"/>
  </joint>

  <link name="rotated_base_link">
    <inertial>
      <mass value="0.0"/>
      <origin rpy="0 0 0" xyz="0.0 0.0 0.0"/>
      <inertia ixx="0.0" ixy="0.0" ixz="0.0" iyy="0.0" iyz="0.0" izz="0.0"/>
    </inertial>
  </link>>

  <joint name="rotated_base-base_fixed_joint" type="fixed">
    <origin xyz="0.0 0.0 0.0" rpy="0.0 0.0 3.141592653589793"/>
    <parent link="rotated_base_link"/>
    <child link="base_link"/>
  </joint>
</robot>
