<?xml version="1.0" ?>
<!-- =================================================================================== -->
<!-- |    This document was autogenerated by xacro from irb2400.xacro                  | -->
<!-- |    EDITING THIS FILE BY HAND IS NOT RECOMMENDED                                 | -->
<!-- =================================================================================== -->
<robot name="abb_irb2400" xmlns:xacro="http://ros.org/wiki/xacro">
  <!-- Conversion were obtained from http://www.e-paint.co.uk/Lab_values.asp
       unless otherwise stated. -->
  <!-- Actual colors -->
  <!-- NCS 2070-Y60R orange, standard robot color 1974 - May 2014 -->
  <!-- RAL 7035 light grey (abb graphite white), standard robot color May 2014 - current -->
  <!-- RAL 9003 signal white (abb white), cleanroom robot color -->
  <!-- RAL 7032 pebble gray, controller -->
  <!-- RAL 7012 basalt gray (abb dark gray) , robot primer -->
  <!-- RAL 7021 black gray (abb black) , robot with dark link color -->
  <!-- Other robot colours availble, but not limited too. -->
  <!-- RAL 3001 signal red -->
  <!-- RAL 3002 carmine red -->
  <!-- RAL 5002 ultramarine blue -->
  <!-- RAL 5015 sky blue -->
  <!-- RAL 6002 leaf green -->
  <!-- RAL 9002 gray white -->
  <!-- RAL 9010 pure white -->
  <!-- approximations -->
  <!-- yellow, collision model -->
  <material name="LightGrey">
    <color rgba="0.8 0.8 0.8 1.0"/>
  </material>

  <material name="DarkGrey">
    <color rgba="0.2 0.2 0.2 1.0"/>
  </material>
  <!-- link list -->
  <link name="base_link">
    <visual>
      <origin rpy="0 0 0" xyz="0 0 0"/>
      <geometry>
        <mesh filename="visual/base_link.dae"/>
      </geometry>
      <material name="LightGrey"/>
      <!-- <material name="">
        <color rgba="0.7372549 0.3490196 0.1607843 1"/>
      </material> -->
    </visual>
    <!-- collision>
      <geometry>
        <mesh filename="collision/base_link.stl"/>
      </geometry>
      <material name="">
        <color rgba="1 1 0 1"/>
      </material>
    </collision -->
  </link>
  <link name="link_1">
    <visual>
      <origin rpy="0 0 0" xyz="0 0 0"/>
      <geometry>
        <mesh filename="visual/link_1.dae"/>
      </geometry>
      <!-- <material name="LightGrey"/> -->
      <material name="DarkGrey"/>
      <!-- <material name="">
        <color rgba="0.7372549 0.3490196 0.1607843 1"/>
      </material> -->
    </visual>
    <collision>
      <origin rpy="0 0 0" xyz="0 0 0"/>
      <geometry>
        <mesh filename="collision/link_1.stl"/>
      </geometry>
      <material name="">
        <color rgba="1 1 0 1"/>
      </material>
    </collision>
  </link>
  <link name="link_2">
    <visual>
      <origin rpy="0 0 0" xyz="0 0 0"/>
      <geometry>
        <mesh filename="visual/link_2.dae"/>
      </geometry>
      <material name="LightGrey"/>
      <!-- <material name="">
        <color rgba="0.7372549 0.3490196 0.1607843 1"/>
      </material> -->
    </visual>
    <collision>
      <origin rpy="0 0 0" xyz="0 0 0"/>
      <geometry>
        <mesh filename="collision/link_2_whole.stl"/>
      </geometry>
      <material name="">
        <color rgba="1 1 0 1"/>
      </material>
    </collision>
  </link>
  <link name="link_3">
    <visual>
      <origin rpy="0 0 0" xyz="0 0 0"/>
      <geometry>
        <mesh filename="visual/link_3.dae"/>
      </geometry>
      <!-- <material name="LightGrey"/> -->
      <material name="DarkGrey"/>
      <!-- <material name="">
        <color rgba="0.7372549 0.3490196 0.1607843 1"/>
      </material> -->
    </visual>
    <collision>
      <origin rpy="0 0 0" xyz="0 0 0"/>
      <geometry>
        <mesh filename="collision/link_3.stl"/>
      </geometry>
      <material name="">
        <color rgba="1 1 0 1"/>
      </material>
    </collision>
  </link>
  <link name="link_4">
    <visual>
      <origin rpy="0 0 0" xyz="0 0 0"/>
      <geometry>
        <mesh filename="visual/link_4.dae"/>
      </geometry>
      <material name="LightGrey"/>
      <!-- <material name="">
        <color rgba="0.7372549 0.3490196 0.1607843 1"/>
      </material> -->
    </visual>
    <collision>
      <origin rpy="0 0 0" xyz="0 0 0"/>
      <geometry>
        <mesh filename="collision/link_4.stl"/>
      </geometry>
      <material name="">
        <color rgba="1 1 0 1"/>
      </material>
    </collision>
  </link>
  <link name="link_5">
    <visual>
      <origin rpy="0 0 0" xyz="0 0 0"/>
      <geometry>
        <mesh filename="visual/link_5.dae"/>
      </geometry>
      <!-- <material name="LightGrey"/> -->
      <material name="DarkGrey"/>
      <!-- <material name="">
        <color rgba="0.7372549 0.3490196 0.1607843 1"/>
      </material> -->
    </visual>
    <collision>
      <origin rpy="0 0 0" xyz="0 0 0"/>
      <geometry>
        <mesh filename="collision/link_5.stl"/>
      </geometry>
      <material name="">
        <color rgba="1 1 0 1"/>
      </material>
    </collision>
  </link>
  <link name="link_6">
    <visual>
      <origin rpy="0 0 0" xyz="0 0 0"/>
      <geometry>
        <mesh filename="visual/link_6.dae"/>
      </geometry>
      <material name="LightGrey"/>
      <!-- <material name="">
        <color rgba="0.1882353 0.1960784 0.2039216 1"/>
      </material> -->
    </visual>
    <collision>
      <origin rpy="0 0 0" xyz="0 0 0"/>
      <geometry>
        <mesh filename="collision/link_6.stl"/>
      </geometry>
      <material name="">
        <color rgba="1 1 0 1"/>
      </material>
    </collision>
  </link>
  <link name="tool_tip"><!-- here -->
    <inertial>
      <mass value="0.0"/>
      <origin rpy="3.14159265359 0 -1.57079632679" xyz="0.0 0.0 0.0"/>
      <inertia ixx="0.0" ixy="0.0" ixz="0.0" iyy="0.0" iyz="0.0" izz="0.0"/>
    </inertial>
    <!-- <visual>
      <geometry>
        <box size="0.01 0.01 0.01"/>
      </geometry>
      <origin rpy="0 0 0" xyz="0 0 0"/>
    </visual> -->
  </link>
  <link name="tool0"/>
  <!-- end of link list -->
  <!-- joint list -->
  <joint name="joint_1" type="revolute">
    <origin rpy="0 0 0" xyz="0 0 0"/>
    <parent link="base_link"/>
    <child link="link_1"/>
    <axis xyz="0 0 1"/>
    <limit effort="0" lower="-3.1416" upper="3.1416" velocity="2.618"/>
    <!-- <limit effort="0" lower="-10" upper="10" velocity="2.618"/> -->
  </joint>
  <joint name="joint_2" type="revolute">
    <origin rpy="0 0 0" xyz="0.1 0 0.615"/>
    <parent link="link_1"/>
    <child link="link_2"/>
    <axis xyz="0 1 0"/>
    <limit effort="0" lower="-1.7453" upper="1.9199" velocity="2.618"/>
    <!-- <limit effort="0" lower="-10" upper="10" velocity="2.618"/> -->
  </joint>
  <joint name="joint_3" type="revolute">
    <origin rpy="0 0 0" xyz="0 0 0.705"/>
    <parent link="link_2"/>
    <child link="link_3"/>
    <axis xyz="0 1 0"/>
    <limit effort="0" lower="-1.0472" upper="1.1345" velocity="2.618"/>
    <!-- <limit effort="0" lower="-10" upper="10" velocity="2.618"/> -->
  </joint>
  <joint name="joint_4" type="revolute">
    <origin rpy="0 0 0" xyz="0.258 0 0.135"/>
    <parent link="link_3"/>
    <child link="link_4"/>
    <axis xyz="1 0 0"/>
    <limit effort="0" lower="-3.49" upper="3.49" velocity="6.2832"/>
    <!-- <limit effort="0" lower="-10" upper="10" velocity="2.618"/> -->
  </joint>
  <joint name="joint_5" type="revolute">
    <origin rpy="0 0 0" xyz="0.497 0 0"/>
    <parent link="link_4"/>
    <child link="link_5"/>
    <axis xyz="0 1 0"/>
    <limit effort="0" lower="-2.0944" upper="2.0944" velocity="6.2832"/>
    <!-- <limit effort="0" lower="-10" upper="10" velocity="2.618"/> -->
  </joint>
  <joint name="joint_6" type="revolute">
    <origin rpy="0 0 0" xyz="0.085 0 0"/>
    <parent link="link_5"/>
    <child link="link_6"/>
    <axis xyz="1 0 0"/>
    <limit effort="0" lower="-6.9813" upper="6.9813" velocity="7.854"/>
    <!-- <limit effort="0" lower="-10" upper="10" velocity="2.618"/> -->
  </joint>
  <joint name="joint_6-tool0" type="fixed">
    <parent link="link_6"/>
    <child link="tool0"/>
    <origin rpy="0 1.57079632679 0" xyz="0 0 0"/>
  </joint>
  <joint name="tool0-tool_tip" type="fixed">  <!-- here -->
    <origin rpy="0 0 0" xyz="0 0 0.12"/>
    <parent link="tool0"/>
    <child link="tool_tip"/>
  </joint>
  <!-- end of joint list -->
  <!-- ROS base_link to ABB World Coordinates transform -->
  <link name="base"/>
  <joint name="base_link-base" type="fixed">
    <origin rpy="0 0 0" xyz="0 0 0"/>
    <parent link="base_link"/>
    <child link="base"/>
  </joint>
</robot>

